<robot name="KUKA_KR_30-3_R2100">
	<link name="base_link">
		<origin xyz="0 0 0.35" rpy="0 0 0"/>
		<visual>
			<material name="blue">
				<color rgba="0 0 .8 1"/>
			</material>
			<geometry>
				<cylinder length="0.7" radius="0.4"/>
			</geometry>
		</visual>
	</link>
	<link name="link1">
		<visual>
			<origin xyz="0.175 0 0.1" rpy="0 1.5707963267948966 0"/>
			<material name="blue">
				<color rgba="0 0 .8 1"/>
			</material>
			<geometry>
				<cylinder length="0.35" radius="0.1"/>
			</geometry>
		</visual>
	</link>
	<joint name="q1" type="revolute">
		<origin xyz="0 0 0.815" rpy="0 0 0"/>
		<parent link="base_link"/>
		<child link="link1"/>
		<axis xyz="0 0 1"/>
		<limit effort="30" velocity="2.44" lower="-3.22" upper="3.22" />
	</joint>

	<link name="link1_passive"/>
	<joint name="q1_passive" type="fixed">
		<origin xyz="0.35 0 0" rpy="1.5707963267948966 0 0"/>
		<parent link="link1"/>
		<child link="link1_passive"/>
	</joint>
	
	<link name="link2"/>
	<joint name="q2" type="revolute">
		<origin xyz="0 0 0" rpy="0 0 1.5707963267948966"/>
		<parent link="link1_passive"/>
		<child link="link2"/>
		<axis xyz="0 0 1"/>
		<limit effort="30" velocity="2.19" lower="-2.18" upper="0.79" />
	</joint>

	<link name="link2_passive"/>
	<joint name="q2_passive" type="fixed">
		<origin xyz="0.85 0 0" rpy="0 0 0"/>
		<parent link="link2"/>
		<child link="link2_passive"/>
	</joint>

	<link name="link3">
		<visual>
			<origin xyz="0.072 0 0" rpy="0 1.5707963267948966 0"/>
			<material name="blue"/>
			<geometry>
				<cylinder length="0.2" radius="0.05"/>
			</geometry>
		</visual>
	</link>
	<joint name="q3" type="revolute">
		<origin xyz="0 0 0" rpy="0 0 0"/>
		<parent link="link2_passive"/>
		<child link="link3"/>
		<axis xyz="0 0 1"/>
		<limit effort="30" velocity="2.44" lower="-1.18" upper="0.52" />
	</joint>

	<link name="link3_passive">
		<visual>
			<origin xyz="0 0 0.41" rpy="0 0 0"/>
			<material name="blue"/>
			<geometry>
				<cylinder length="0.82" radius="0.05"/>
			</geometry>
		</visual>
	</link>
	<joint name="q3_passive" type="fixed">
		<origin xyz="0.145 0 0" rpy="1.5707963267948966 0 0"/>
		<parent link="link3"/>
		<child link="link3_passive"/>
	</joint>
	
	<link name="link4"/>
	<joint name="q4" type="revolute">
		<origin xyz="0 0 0.82" rpy="0 0 0"/>
		<parent link="link3_passive"/>
		<child link="link4"/>
		<axis xyz="0 0 1"/>
		<limit effort="30" velocity="4.53" lower="-6.11" upper="6.11" />	
	</joint>

	<link name="link4_passive"/>
	<joint name="q4_passive" type="fixed">
		<origin xyz="0 0 0" rpy="-1.5707963267948966 0 0"/>
		<parent link="link4"/>
		<child link="link4_passive"/>
	</joint>
	
	<link name="link5"/>
	<joint name="q5" type="revolute">
		<origin xyz="0 0 0" rpy="0 0 0"/>
		<parent link="link4_passive"/>
		<child link="link5"/>
		<axis xyz="0 0 1"/>
		<limit effort="30" velocity="4.27" lower="-2.07" upper="2.07" />
	</joint>

	<link name="link5_passive">
		<visual>
			<origin xyz="0 0 0.085" rpy="0 0 0"/>
			<material name="blue"/>
			<geometry>
				<cylinder length="0.17" radius="0.05"/>
			</geometry>
		</visual>
	</link>
	<joint name="q5_passive" type="fixed">
		<origin xyz="0 0 0" rpy="1.5707963267948966 0 0"/>
		<parent link="link5"/>
		<child link="link5_passive"/>
	</joint>
	
	<link name="link6">
		<visual>
			<origin xyz="0 0 0" rpy="0 0 0"/>
			<material name="blue"/>
			<geometry>
				<box size="0.1 0.1 0.05"/>
			</geometry>
		</visual>
	</link>
	<joint name="q6" type="revolute">
		<origin xyz="0 0 0.17" rpy="0 0 0"/>
		<parent link="link5_passive"/>
		<child link="link6"/>
		<axis xyz="0 0 1"/>
		<limit effort="30" velocity="5.61" lower="-6.11" upper="6.11" />
	</joint>
</robot>
